Workbook

Sheet README
A1: PlotArmour: Verity & Studio Master Reference
A2: Single source of truth for sales, outreach, product and engineering. If this workbook and anything else disagree, fix this one first.
A4: Last refreshed | B4: 2026-10-06
A5: Rule | B5: Edit here first. Website copy, decks and quotes follow this workbook.
A6: Code snapshot | B6: D:/Code/verity main and D:/Code/verity-explore, scanned 2026-10-06
A7: Site base URL | B7: https://verity.plotarmour.in
A8: Owner
A10: Start here
A11: Sales / account managers | B11: Quick Quote, Packages, Package Matrix, Modules (filter Sellable today = Yes), Pricing Rules, Biz FAQ, Website Capabilities (language rules)
A12: Outreach managers and teams | B12: Business Types (targeting, pain points, discovery question), Biz Pain Points, Biz Roles, Biz Use Cases, Biz AI Questions, Industries
A13: Product managers | B13: Modules, Roadmap & Gaps, Pricing Review, Package Matrix, Dev Capabilities, Biz Modules (what the website promises)
A14: Developers | B14: Dev Capabilities, Dev Commands, Dev Queries, Dev Events, Dev Data Model, Dev Platform, Dev Screens
A15: Finance / leadership | B15: Pricing Rules, Packages, Customization Rates, Pricing Review, Studio Services, Studio Packages
A17: Status legend (Modules tab) | C17: Modules
A18: Live | B18: In product code and usable. | C18: =COUNTIF(Modules!$F$5:$F$116,A18)
A19: Live (client-built) | B19: Built for one client, reusable without a fork. | C19: =COUNTIF(Modules!$F$5:$F$116,A19)
A20: Partial | B20: Works with stated limits. | C20: =COUNTIF(Modules!$F$5:$F$116,A20)
A21: Built, not live-verified | B21: Code exists, no real-world call yet. Do not sell. | C21: =COUNTIF(Modules!$F$5:$F$116,A21)
A22: Designed | B22: Specification only. | C22: =COUNTIF(Modules!$F$5:$F$116,A22)
A23: Planned | B23: Named, no design or code. | C23: =COUNTIF(Modules!$F$5:$F$116,A23)
A24: Reference | B24: Research only. | C24: =COUNTIF(Modules!$F$5:$F$116,A24)
A26: Tab index
A27: Tab | B27: What it holds | C27: Rows | D27: Audience
A28: README | B28: This page | D28: Everyone
A29: Quick Quote | B29: Price a deal: package, add-ons, customization, GST | D29: Sales
A30: Packages | B30: The seven Verity packages and floors | C30: =COUNTA('Packages'!A:A)-3 | D30: Sales
A31: Package Matrix | B31: Which module is in which package | C31: =COUNTA('Package Matrix'!A:A)-3 | D31: Sales
A32: Modules | B32: Every module with status, price class and pitch | C32: =COUNTA('Modules'!A:A)-3 | D32: Everyone
A33: Pricing Rules | B33: Inputs behind every price formula plus policy | D33: Pricing / finance
A34: Customization Rates | B34: Per-item rate card | C34: =COUNTA('Customization Rates'!A:A)-3 | D34: Pricing / finance
A35: Pricing Review | B35: Open conflicts in the commercial model | C35: =COUNTA('Pricing Review'!A:A)-3 | D35: Product
A36: Roadmap & Gaps | B36: Unbuilt and partial items with blockers | C36: =COUNTA('Roadmap & Gaps'!A:A)-3 | D36: Product
A37: Industries | B37: Nine industry hubs | C37: =COUNTA('Industries'!A:A)-3 | D37: Outreach
A38: Business Types | B38: 123 business types for outreach targeting | C38: =COUNTA('Business Types'!A:A)-3 | D38: Outreach
A39: Biz Modules | B39: Business pages: modules for every business type | C39: =COUNTA('Biz Modules'!A:A)-3 | D39: Sales
A40: Biz Workflows | B40: Business pages: workflows for every business type | C40: =COUNTA('Biz Workflows'!A:A)-3 | D40: Sales
A41: Biz Automations | B41: Business pages: automations for every business type | C41: =COUNTA('Biz Automations'!A:A)-3 | D41: Sales
A42: Biz Reports | B42: Business pages: reports for every business type | C42: =COUNTA('Biz Reports'!A:A)-3 | D42: Sales
A43: Biz Roles | B43: Business pages: roles for every business type | C43: =COUNTA('Biz Roles'!A:A)-3 | D43: Sales
A44: Biz Use Cases | B44: Business pages: use cases for every business type | C44: =COUNTA('Biz Use Cases'!A:A)-3 | D44: Sales
...

Sheet Quick Quote
A1: Quick Quote
A2: Blue cells are inputs. Proposed 2026 list rates, ex-GST. Read Pricing Review before sending any number to a client. Example rows are pre-filled: overwrite them.
A4: Package | B4: Verity Trade | D4: Package setup (floor) | E4: =INDEX(Packages!$E$5:$E$11,MATCH($B$4,Packages!$A$5:$A$11,0))
A5: Total locations | B5: 2 | D5: Extra locations setup | E5: =MAX($B$5-1,0)*'Pricing Rules'!$B$13
A6: Billing | B6: Annual | D6: Add-on modules setup | E6: =SUM(C21:C40)
A7: GST rate | B7: ='Pricing Rules'!B11 | D7: Customization one-time | E7: =SUM(F44:F58)
A8: Annual prepay discount | B8: ='Pricing Rules'!B12 | D8: TOTAL ONE-TIME (ex-GST) | E8: =SUM(E4:E7)
D9: Package monthly (floor) | E9: =INDEX(Packages!$H$5:$H$11,MATCH($B$4,Packages!$A$5:$A$11,0))
A10: Rules | D10: Extra locations monthly | E10: =MAX($B$5-1,0)*'Pricing Rules'!$B$14
A11: Package floors are minimums; final price depends on scope. | D11: Add-on modules monthly | E11: =SUM(D21:D40)
A12: Add-on = built module priced from Modules. Roadmap = not built, price is 0 and it must not be promised. | D12: Customization monthly | E12: =SUM(G44:G58)
A13: Included modules cost nothing extra. Package contents live on Package Matrix. | D13: TOTAL MONTHLY, list (ex-GST) | E13: =SUM(E9:E12)
A14: Customization rows read the Customization Rates tab by tier; monthly items go to the monthly total. | D14: Monthly after billing choice | E14: =IF($B$6="Annual",E13*(1-$B$8),E13)
A15: Hosting, third-party messaging, AI usage and data migration are quoted separately (Pricing Rules policy). | D15: FIRST-YEAR TOTAL (ex-GST) | E15: =E8+12*E14
D16: GST | E16: =E15*$B$7
D17: FIRST-YEAR TOTAL (incl. GST) | E17: =E15+E16
D18: Recommended minimum check | E18: =IF(AND(E8>='Pricing Rules'!$B$15,E13>='Pricing Rules'!$B$16),"Meets recommended minimum","Below recommended minimum (see Pricing Review 1, 2)")
A20: Add-on module | B20: Package status | C20: Setup | D20: Monthly | E20: Note
A21: Recipes & Food Cost | B21: =IF(A21="","",IFERROR(INDEX('Package Matrix'!$D$5:$J$116,MATCH(A21,'Package Matrix'!$B$5:$B$116,0),MATCH($B$4,'Package Matrix'!$D$4:$J$4,0)),"Not found")) | C21: =IF(OR(A21="",B21="Included",B21="Roadmap",B21="Internal",B21="Not found"),0,INDEX(Modules!$K$5:$K$116,MATCH(A21,Modules!$C$5:$C$116,0))) | D21: =IF(OR(A21="",B21="Included",B21="Roadmap",B21="Internal",B21="Not found"),0,INDEX(Modules!$L$5:$L$116,MATCH(A21,Modules!$C$5:$C$116,0))) | E21: =IF(B21="Roadmap","Not built: cannot be sold as a deliverable",IF(B21="Included","Already in package",IF(B21="Not found","Pick from the list",IF(A21="","",IF(INDEX(Modules!$F$5:$F$116,MATCH(A21,Modules!$C$5:$C$116,0))="Partial","Partial: check limits in Modules","")))))
A22: Dine-in Floor & Tables | B22: =IF(A22="","",IFERROR(INDEX('Package Matrix'!$D$5:$J$116,MATCH(A22,'Package Matrix'!$B$5:$B$116,0),MATCH($B$4,'Package Matrix'!$D$4:$J$4,0)),"Not found")) | C22: =IF(OR(A22="",B22="Included",B22="Roadmap",B22="Internal",B22="Not found"),0,INDEX(Modules!$K$5:$K$116,MATCH(A22,Modules!$C$5:$C$116,0))) | D22: =IF(OR(A22="",B22="Included",B22="Roadmap",B22="Internal",B22="Not found"),0,INDEX(Modules!$L$5:$L$116,MATCH(A22,Modules!$C$5:$C$116,0))) | E22: =IF(B22="Roadmap","Not built: cannot be sold as a deliverable",IF(B22="Included","Already in package",IF(B22="Not found","Pick from the list",IF(A22="","",IF(INDEX(Modules!$F$5:$F$116,MATCH(A22,Modules!$C$5:$C$116,0))="Partial","Partial: check limits in Modules","")))))
A23: Attendance & Shifts | B23: =IF(A23="","",IFERROR(INDEX('Package Matrix'!$D$5:$J$116,MATCH(A23,'Package Matrix'!$B$5:$B$116,0),MATCH($B$4,'Package Matrix'!$D$4:$J$4,0)),"Not found")) | C23: =IF(OR(A23="",B23="Included",B23="Roadmap",B23="Internal",B23="Not found"),0,INDEX(Modules!$K$5:$K$116,MATCH(A23,Modules!$C$5:$C$116,0))) | D23: =IF(OR(A23="",B23="Included",B23="Roadmap",B23="Internal",B23="Not found"),0,INDEX(Modules!$L$5:$L$116,MATCH(A23,Modules!$C$5:$C$116,0))) | E23: =IF(B23="Roadmap","Not built: cannot be sold as a deliverable",IF(B23="Included","Already in package",IF(B23="Not found","Pick from the list",IF(A23="","",IF(INDEX(Modules!$F$5:$F$116,MATCH(A23,Modules!$C$5:$C$116,0))="Partial","Partial: check limits in Modules","")))))
B24: =IF(A24="","",IFERROR(INDEX('Package Matrix'!$D$5:$J$116,MATCH(A24,'Package Matrix'!$B$5:$B$116,0),MATCH($B$4,'Package Matrix'!$D$4:$J$4,0)),"Not found")) | C24: =IF(OR(A24="",B24="Included",B24="Roadmap",B24="Internal",B24="Not found"),0,INDEX(Modules!$K$5:$K$116,MATCH(A24,Modules!$C$5:$C$116,0))) | D24: =IF(OR(A24="",B24="Included",B24="Roadmap",B24="Internal",B24="Not found"),0,INDEX(Modules!$L$5:$L$116,MATCH(A24,Modules!$C$5:$C$116,0))) | E24: =IF(B24="Roadmap","Not built: cannot be sold as a deliverable",IF(B24="Included","Already in package",IF(B24="Not found","Pick from the list",IF(A24="","",IF(INDEX(Modules!$F$5:$F$116,MATCH(A24,Modules!$C$5:$C$116,0))="Partial","Partial: check limits in Modules","")))))
B25: =IF(A25="","",IFERROR(INDEX('Package Matrix'!$D$5:$J$116,MATCH(A25,'Package Matrix'!$B$5:$B$116,0),MATCH($B$4,'Package Matrix'!$D$4:$J$4,0)),"Not found")) | C25: =IF(OR(A25="",B25="Included",B25="Roadmap",B25="Internal",B25="Not found"),0,INDEX(Modules!$K$5:$K$116,MATCH(A25,Modules!$C$5:$C$116,0))) | D25: =IF(OR(A25="",B25="Included",B25="Roadmap",B25="Internal",B25="Not found"),0,INDEX(Modules!$L$5:$L$116,MATCH(A25,Modules!$C$5:$C$116,0))) | E25: =IF(B25="Roadmap","Not built: cannot be sold as a deliverable",IF(B25="Included","Already in package",IF(B25="Not found","Pick from the list",IF(A25="","",IF(INDEX(Modules!$F$5:$F$116,MATCH(A25,Modules!$C$5:$C$116,0))="Partial","Partial: check limits in Modules","")))))
B26: =IF(A26="","",IFERROR(INDEX('Package Matrix'!$D$5:$J$116,MATCH(A26,'Package Matrix'!$B$5:$B$116,0),MATCH($B$4,'Package Matrix'!$D$4:$J$4,0)),"Not found")) | C26: =IF(OR(A26="",B26="Included",B26="Roadmap",B26="Internal",B26="Not found"),0,INDEX(Modules!$K$5:$K$116,MATCH(A26,Modules!$C$5:$C$116,0))) | D26: =IF(OR(A26="",B26="Included",B26="Roadmap",B26="Internal",B26="Not found"),0,INDEX(Modules!$L$5:$L$116,MATCH(A26,Modules!$C$5:$C$116,0))) | E26: =IF(B26="Roadmap","Not built: cannot be sold as a deliverable",IF(B26="Included","Already in package",IF(B26="Not found","Pick from the list",IF(A26="","",IF(INDEX(Modules!$F$5:$F$116,MATCH(A26,Modules!$C$5:$C$116,0))="Partial","Partial: check limits in Modules","")))))
B27: =IF(A27="","",IFERROR(INDEX('Package Matrix'!$D$5:$J$116,MATCH(A27,'Package Matrix'!$B$5:$B$116,0),MATCH($B$4,'Package Matrix'!$D$4:$J$4,0)),"Not found")) | C27: =IF(OR(A27="",B27="Included",B27="Roadmap",B27="Internal",B27="Not found"),0,INDEX(Modules!$K$5:$K$116,MATCH(A27,Modules!$C$5:$C$116,0))) | D27: =IF(OR(A27="",B27="Included",B27="Roadmap",B27="Internal",B27="Not found"),0,INDEX(Modules!$L$5:$L$116,MATCH(A27,Modules!$C$5:$C$116,0))) | E27: =IF(B27="Roadmap","Not built: cannot be sold as a deliverable",IF(B27="Included","Already in package",IF(B27="Not found","Pick from the list",IF(A27="","",IF(INDEX(Modules!$F$5:$F$116,MATCH(A27,Modules!$C$5:$C$116,0))="Partial","Partial: check limits in Modules","")))))
B28: =IF(A28="","",IFERROR(INDEX('Package Matrix'!$D$5:$J$116,MATCH(A28,'Package Matrix'!$B$5:$B$116,0),MATCH($B$4,'Package Matrix'!$D$4:$J$4,0)),"Not found")) | C28: =IF(OR(A28="",B28="Included",B28="Roadmap",B28="Internal",B28="Not found"),0,INDEX(Modules!$K$5:$K$116,MATCH(A28,Modules!$C$5:$C$116,0))) | D28: =IF(OR(A28="",B28="Included",B28="Roadmap",B28="Internal",B28="Not found"),0,INDEX(Modules!$L$5:$L$116,MATCH(A28,Modules!$C$5:$C$116,0))) | E28: =IF(B28="Roadmap","Not built: cannot be sold as a deliverable",IF(B28="Included","Already in package",IF(B28="Not found","Pick from the list",IF(A28="","",IF(INDEX(Modules!$F$5:$F$116,MATCH(A28,Modules!$C$5:$C$116,0))="Partial","Partial: check limits in Modules","")))))
B29: =IF(A29="","",IFERROR(INDEX('Package Matrix'!$D$5:$J$116,MATCH(A29,'Package Matrix'!$B$5:$B$116,0),MATCH($B$4,'Package Matrix'!$D$4:$J$4,0)),"Not found")) | C29: =IF(OR(A29="",B29="Included",B29="Roadmap",B29="Internal",B29="Not found"),0,INDEX(Modules!$K$5:$K$116,MATCH(A29,Modules!$C$5:$C$116,0))) | D29: =IF(OR(A29="",B29="Included",B29="Roadmap",B29="Internal",B29="Not found"),0,INDEX(Modules!$L$5:$L$116,MATCH(A29,Modules!$C$5:$C$116,0))) | E29: =IF(B29="Roadmap","Not built: cannot be sold as a deliverable",IF(B29="Included","Already in package",IF(B29="Not found","Pick from the list",IF(A29="","",IF(INDEX(Modules!$F$5:$F$116,MATCH(A29,Modules!$C$5:$C$116,0))="Partial","Partial: check limits in Modules","")))))
B30: =IF(A30="","",IFERROR(INDEX('Package Matrix'!$D$5:$J$116,MATCH(A30,'Package Matrix'!$B$5:$B$116,0),MATCH($B$4,'Package Matrix'!$D$4:$J$4,0)),"Not found")) | C30: =IF(OR(A30="",B30="Included",B30="Roadmap",B30="Internal",B30="Not found"),0,INDEX(Modules!$K$5:$K$116,MATCH(A30,Modules!$C$5:$C$116,0))) | D30: =IF(OR(A30="",B30="Included",B30="Roadmap",B30="Internal",B30="Not found"),0,INDEX(Modules!$L$5:$L$116,MATCH(A30,Modules!$C$5:$C$116,0))) | E30: =IF(B30="Roadmap","Not built: cannot be sold as a deliverable",IF(B30="Included","Already in package",IF(B30="Not found","Pick from the list",IF(A30="","",IF(INDEX(Modules!$F$5:$F$116,MATCH(A30,Modules!$C$5:$C$116,0))="Partial","Partial: check limits in Modules","")))))
B31: =IF(A31="","",IFERROR(INDEX('Package Matrix'!$D$5:$J$116,MATCH(A31,'Package Matrix'!$B$5:$B$116,0),MATCH($B$4,'Package Matrix'!$D$4:$J$4,0)),"Not found")) | C31: =IF(OR(A31="",B31="Included",B31="Roadmap",B31="Internal",B31="Not found"),0,INDEX(Modules!$K$5:$K$116,MATCH(A31,Modules!$C$5:$C$116,0))) | D31: =IF(OR(A31="",B31="Included",B31="Roadmap",B31="Internal",B31="Not found"),0,INDEX(Modules!$L$5:$L$116,MATCH(A31,Modules!$C$5:$C$116,0))) | E31: =IF(B31="Roadmap","Not built: cannot be sold as a deliverable",IF(B31="Included","Already in package",IF(B31="Not found","Pick from the list",IF(A31="","",IF(INDEX(Modules!$F$5:$F$116,MATCH(A31,Modules!$C$5:$C$116,0))="Partial","Partial: check limits in Modules","")))))
B32: =IF(A32="","",IFERROR(INDEX('Package Matrix'!$D$5:$J$116,MATCH(A32,'Package Matrix'!$B$5:$B$116,0),MATCH($B$4,'Package Matrix'!$D$4:$J$4,0)),"Not found")) | C32: =IF(OR(A32="",B32="Included",B32="Roadmap",B32="Internal",B32="Not found"),0,INDEX(Modules!$K$5:$K$116,MATCH(A32,Modules!$C$5:$C$116,0))) | D32: =IF(OR(A32="",B32="Included",B32="Roadmap",B32="Internal",B32="Not found"),0,INDEX(Modules!$L$5:$L$116,MATCH(A32,Modules!$C$5:$C$116,0))) | E32: =IF(B32="Roadmap","Not built: cannot be sold as a deliverable",IF(B32="Included","Already in package",IF(B32="Not found","Pick from the list",IF(A32="","",IF(INDEX(Modules!$F$5:$F$116,MATCH(A32,Modules!$C$5:$C$116,0))="Partial","Partial: check limits in Modules","")))))
B33: =IF(A33="","",IFERROR(INDEX('Package Matrix'!$D$5:$J$116,MATCH(A33,'Package Matrix'!$B$5:$B$116,0),MATCH($B$4,'Package Matrix'!$D$4:$J$4,0)),"Not found")) | C33: =IF(OR(A33="",B33="Included",B33="Roadmap",B33="Internal",B33="Not found"),0,INDEX(Modules!$K$5:$K$116,MATCH(A33,Modules!$C$5:$C$116,0))) | D33: =IF(OR(A33="",B33="Included",B33="Roadmap",B33="Internal",B33="Not found"),0,INDEX(Modules!$L$5:$L$116,MATCH(A33,Modules!$C$5:$C$116,0))) | E33: =IF(B33="Roadmap","Not built: cannot be sold as a deliverable",IF(B33="Included","Already in package",IF(B33="Not found","Pick from the list",IF(A33="","",IF(INDEX(Modules!$F$5:$F$116,MATCH(A33,Modules!$C$5:$C$116,0))="Partial","Partial: check limits in Modules","")))))
B34: =IF(A34="","",IFERROR(INDEX('Package Matrix'!$D$5:$J$116,MATCH(A34,'Package Matrix'!$B$5:$B$116,0),MATCH($B$4,'Package Matrix'!$D$4:$J$4,0)),"Not found")) | C34: =IF(OR(A34="",B34="Included",B34="Roadmap",B34="Internal",B34="Not found"),0,INDEX(Modules!$K$5:$K$116,MATCH(A34,Modules!$C$5:$C$116,0))) | D34: =IF(OR(A34="",B34="Included",B34="Roadmap",B34="Internal",B34="Not found"),0,INDEX(Modules!$L$5:$L$116,MATCH(A34,Modules!$C$5:$C$116,0))) | E34: =IF(B34="Roadmap","Not built: cannot be sold as a deliverable",IF(B34="Included","Already in package",IF(B34="Not found","Pick from the list",IF(A34="","",IF(INDEX(Modules!$F$5:$F$116,MATCH(A34,Modules!$C$5:$C$116,0))="Partial","Partial: check limits in Modules","")))))
B35: =IF(A35="","",IFERROR(INDEX('Package Matrix'!$D$5:$J$116,MATCH(A35,'Package Matrix'!$B$5:$B$116,0),MATCH($B$4,'Package Matrix'!$D$4:$J$4,0)),"Not found")) | C35: =IF(OR(A35="",B35="Included",B35="Roadmap",B35="Internal",B35="Not found"),0,INDEX(Modules!$K$5:$K$116,MATCH(A35,Modules!$C$5:$C$116,0))) | D35: =IF(OR(A35="",B35="Included",B35="Roadmap",B35="Internal",B35="Not found"),0,INDEX(Modules!$L$5:$L$116,MATCH(A35,Modules!$C$5:$C$116,0))) | E35: =IF(B35="Roadmap","Not built: cannot be sold as a deliverable",IF(B35="Included","Already in package",IF(B35="Not found","Pick from the list",IF(A35="","",IF(INDEX(Modules!$F$5:$F$116,MATCH(A35,Modules!$C$5:$C$116,0))="Partial","Partial: check limits in Modules","")))))
... B40: =IF(A40="","",IFERROR(INDEX('Package Matrix'!$D$5:$J$116,MATCH(A40,'Package Matrix'!$B$5:$B$116,0),MATCH($B$4,'Package Matrix'!$D$4:$J$4,0)),"Not found")) | C40: =IF(OR(A40="",B40="Included",B40="Roadmap",B40="Internal",B40="Not found"),0,INDEX(Modules!$K$5:$K$116,MATCH(A40,Modules!$C$5:$C$116,0))) | D40: =IF(OR(A40="",B40="Included",B40="Roadmap",B40="Internal",B40="Not found"),0,INDEX(Modules!$L$5:$L$116,MATCH(A40,Modules!$C$5:$C$116,0))) | E40: =IF(B40="Roadmap","Not built: cannot be sold as a deliverable",IF(B40="Included","Already in package",IF(B40="Not found","Pick from the list",IF(A40="","",IF(INDEX(Modules!$F$5:$F$116,MATCH(A40,Modules!$C$5:$C$116,0))="Partial","Partial: check limits in Modules","")))))
A42: Customization
A43: Customization | B43: Tier | C43: Qty | D43: Unit price | E43: Charge type | F43: One-time total | G43: Monthly total
A44: Approval workflow | B44: Standard | C44: 2 | D44: =IF(A44="","",IFERROR(INDEX('Customization Rates'!$C$5:$E$22,MATCH(A44,'Customization Rates'!$A$5:$A$22,0),MATCH(B44,'Customization Rates'!$C$4:$E$4,0)),0)) | E44: =IF(A44="","",IFERROR(INDEX('Customization Rates'!$F$5:$F$22,MATCH(A44,'Customization Rates'!$A$5:$A$22,0)),"")) | F44: =IF(OR(A44="",E44="Monthly"),0,D44*C44) | G44: =IF(AND(A44<>"",E44="Monthly"),D44*C44,0)
A45: Custom report | B45: Basic | C45: 3 | D45: =IF(A45="","",IFERROR(INDEX('Customization Rates'!$C$5:$E$22,MATCH(A45,'Customization Rates'!$A$5:$A$22,0),MATCH(B45,'Customization Rates'!$C$4:$E$4,0)),0)) | E45: =IF(A45="","",IFERROR(INDEX('Customization Rates'!$F$5:$F$22,MATCH(A45,'Customization Rates'!$A$5:$A$22,0)),"")) | F45: =IF(OR(A45="",E45="Monthly"),0,D45*C45) | G45: =IF(AND(A45<>"",E45="Monthly"),D45*C45,0)
A46: Data migration | B46: Standard | C46: 1 | D46: =IF(A46="","",IFERROR(INDEX('Customization Rates'!$C$5:$E$22,MATCH(A46,'Customization Rates'!$A$5:$A$22,0),MATCH(B46,'Customization Rates'!$C$4:$E$4,0)),0)) | E46: =IF(A46="","",IFERROR(INDEX('Customization Rates'!$F$5:$F$22,MATCH(A46,'Customization Rates'!$A$5:$A$22,0)),"")) | F46: =IF(OR(A46="",E46="Monthly"),0,D46*C46) | G46: =IF(AND(A46<>"",E46="Monthly"),D46*C46,0)
D47: =IF(A47="","",IFERROR(INDEX('Customization Rates'!$C$5:$E$22,MATCH(A47,'Customization Rates'!$A$5:$A$22,0),MATCH(B47,'Customization Rates'!$C$4:$E$4,0)),0)) | E47: =IF(A47="","",IFERROR(INDEX('Customization Rates'!$F$5:$F$22,MATCH(A47,'Customization Rates'!$A$5:$A$22,0)),"")) | F47: =IF(OR(A47="",E47="Monthly"),0,D47*C47) | G47: =IF(AND(A47<>"",E47="Monthly"),D47*C47,0)
...

Sheet Packages
A1: Verity Packages
A2: Numeric floors (blue) drive Quick Quote. Fees marked + are floors, final price depends on scope. Prices are proposed 2026 rates, ex-GST.
A4: Package | B4: Positioning | C4: Scope (as sold) | D4: Implementation fee (as sold) | E4: Setup floor | F4: Open-ended? | G4: Platform fee (as sold) | H4: Monthly floor | I4: Ideal customer | J4: First year, monthly billing | K4: First year, annual prepay | L4: Modules included | M4: Known scope gaps | N4: Meets recommended minimum?
A5: Verity Core | B5: Core business operations | C5: CRM; customers; leads; quotations; sales orders; invoicing; basic inventory; dashboards; users/roles | D5: ₹40,000+ setup | E5: 40000 | F5: Yes | G5: ₹2,000/mo | H5: 2000 | I5: Best for service/professional MSMEs | J5: =E5+12*H5 | K5: =E5+12*H5*(1-'Pricing Rules'!$B$12) | L5: ='Package Matrix'!D118 | M5: Quotations (M152) not built. Leads use the outreach pipeline (M120). | N5: =IF(AND(E5>='Pricing Rules'!$B$15,H5>='Pricing Rules'!$B$16),"Yes","Below minimum")
A6: Verity Trade | B6: Trading / distribution | C6: Core + procurement; vendors; purchase orders; inventory; warehouses; stock controls; receivables; | D6: ₹50,000+ setup | E6: 50000 | F6: Yes | G6: ₹3,000/mo | H6: 3000 | I6: For distributors, dealers and trading businesses | J6: =E6+12*H6 | K6: =E6+12*H6*(1-'Pricing Rules'!$B$12) | L6: ='Package Matrix'!E118 | M6: Inherits Core gap: quotations (M152). | N6: =IF(AND(E6>='Pricing Rules'!$B$15,H6>='Pricing Rules'!$B$16),"Yes","Below minimum")
A7: Verity Services | B7: Service businesses | C7: Core + projects; jobs; scheduling; timesheets; work logs; service workflows; customer portal-ready architecture | D7: ₹75,000+ setup | E7: 75000 | F7: Yes | G7: ₹5,000/mo | H7: 5000 | I7: For consulting, agencies, engineering, legal/accounting and field services | J7: =E7+12*H7 | K7: =E7+12*H7*(1-'Pricing Rules'!$B$12) | L7: ='Package Matrix'!F118 | M7: Projects, timesheets, customer portal (M153, M154) not built. Core gap M152. | N7: =IF(AND(E7>='Pricing Rules'!$B$15,H7>='Pricing Rules'!$B$16),"Yes","Below minimum")
A8: Verity Production | B8: Manufacturing | C8: Core + inventory; BOM; production planning; work orders; material consumption; QC; wastage; shop-floor workflows | D8: ₹90,000+ setup | E8: 90000 | F8: Yes | G8: ₹8,000/mo | H8: 8000 | I8: For small and mid-sized manufacturers | J8: =E8+12*H8 | K8: =E8+12*H8*(1-'Pricing Rules'!$B$12) | L8: ='Package Matrix'!G118 | M8: Wastage exists (M061); advanced QC (M109) and MRP (M110) not built. | N8: =IF(AND(E8>='Pricing Rules'!$B$15,H8>='Pricing Rules'!$B$16),"Yes","Below minimum")
A9: Verity Manufacturing Plus | B9: Advanced manufacturing | C9: Production + advanced QC; multi-level BOM; revisions; job tracking; dashboards; approvals; traceability; integrations | D9: ₹1,25,000+ setup | E9: 125000 | F9: Yes | G9: ₹10,000/mo | H9: 10000 | I9: For more complex factories | J9: =E9+12*H9 | K9: =E9+12*H9*(1-'Pricing Rules'!$B$12) | L9: ='Package Matrix'!H118 | M9: Multi-level BOM revisions, advanced QC, approvals on production not confirmed (M109). | N9: =IF(AND(E9>='Pricing Rules'!$B$15,H9>='Pricing Rules'!$B$16),"Yes","Below minimum")
A10: Verity Enterprise | B10: Multi-function enterprise | C10: Custom combination of CRM, sales, procurement, inventory, production, projects, workforce, finance, QC, analytics and integrations | D10: ₹1,50,000+ setup | E10: 150000 | F10: Yes | G10: ₹12,000+/mo | H10: 12000 | I10: Custom architecture and SLA | J10: =E10+12*H10 | K10: =E10+12*H10*(1-'Pricing Rules'!$B$12) | L10: ='Package Matrix'!I118 | M10: Roadmap items cannot be sold until built; see Roadmap & Gaps. | N10: =IF(AND(E10>='Pricing Rules'!$B$15,H10>='Pricing Rules'!$B$16),"Yes","Below minimum")
A11: Verity Dedicated | B11: Dedicated business OS | C11: Dedicated environment; custom modules; custom workflows; integrations; PWA/offline; priority support; dedicated roadmap | D11: ₹1,80,000 | E11: 180000 | F11: No | G11: ₹15,000/mo | H11: 15000 | I11: For organizations requiring deep adaptation | J11: =E11+12*H11 | K11: =E11+12*H11*(1-'Pricing Rules'!$B$12) | L11: ='Package Matrix'!J118 | M11: Dedicated environment is an ops service (HQ console M016), not a product SKU in code. | N11: =IF(AND(E11>='Pricing Rules'!$B$15,H11>='Pricing Rules'!$B$16),"Yes","Below minimum")

Sheet Package Matrix
A1: Package x Module Matrix
A2: Included = in the package price. Add-on = built, priced from Modules. Roadmap = not built, cannot be quoted as a deliverable. Edit a cell to change a package definition.
A4: ID | B4: Module | C4: Status | D4: Verity Core | E4: Verity Trade | F4: Verity Services | G4: Verity Production | H4: Verity Manufacturing Plus | I4: Verity Enterprise | J4: Verity Dedicated
A5: M001 | B5: Tenancy & Organizations | C5: Live | D5: Included | E5: Included | F5: Included | G5: Included | H5: Included | I5: Included | J5: Included
A6: M002 | B6: Users, Roles & Permissions | C6: Live | D6: Included | E6: Included | F6: Included | G6: Included | H6: Included | I6: Included | J6: Included
A7: M003 | B7: SSO / OIDC Login | C7: Live | D7: Included | E7: Included | F7: Included | G7: Included | H7: Included | I7: Included | J7: Included
A8: M004 | B8: Audit Trail & Activity History | C8: Live | D8: Included | E8: Included | F8: Included | G8: Included | H8: Included | I8: Included | J8: Included
A9: M005 | B9: Workflow & State Engine | C9: Live | D9: Included | E9: Included | F9: Included | G9: Included | H9: Included | I9: Included | J9: Included
A10: M006 | B10: Approvals | C10: Live | D10: Included | E10: Included | F10: Included | G10: Included | H10: Included | I10: Included | J10: Included
A11: M007 | B11: Notifications | C11: Partial | D11: Included | E11: Included | F11: Included | G11: Included | H11: Included | I11: Included | J11: Included
A12: M008 | B12: SLA Clocks & Business Calendar | C12: Live | D12: Included | E12: Included | F12: Included | G12: Included | H12: Included | I12: Included | J12: Included
A13: M009 | B13: Custom Fields & Configuration | C13: Live | D13: Included | E13: Included | F13: Included | G13: Included | H13: Included | I13: Included | J13: Included
A14: M010 | B14: Industry Packs & Templates | C14: Live | D14: Included | E14: Included | F14: Included | G14: Included | H14: Included | I14: Included | J14: Included
A15: M011 | B15: Capability Activation & Upgrades | C15: Live | D15: Included | E15: Included | F15: Included | G15: Included | H15: Included | I15: Included | J15: Included
... A116: M160 | B116: Custom Report Builder | C116: Planned | D116: Roadmap | E116: Roadmap | F116: Roadmap | G116: Roadmap | H116: Roadmap | I116: Roadmap | J116: Roadmap
B118: Modules included | D118: =COUNTIF(D5:D116,"Included") | E118: =COUNTIF(E5:E116,"Included") | F118: =COUNTIF(F5:F116,"Included") | G118: =COUNTIF(G5:G116,"Included") | H118: =COUNTIF(H5:H116,"Included") | I118: =COUNTIF(I5:I116,"Included") | J118: =COUNTIF(J5:J116,"Included")

Sheet Modules
A1: Verity Module Catalogue
A2: 112 modules. Status is verified against the Verity codebase as of 2026-10-06. Add-on prices are formulas driven by Complexity and Pricing Rules.
A4: ID | B4: Group | C4: Module | D4: What the customer gets | E4: Key features | F4: Status | G4: Proof client | H4: Code reference | I4: Complexity | J4: Depends on | K4: Add-on setup | L4: Add-on monthly | M4: Sellable today? | N4: Sales pitch line | O4: Dev / PM notes
A5: M001 | B5: Platform Foundation | C5: Tenancy & Organizations | D5: Every client gets an isolated workspace with its own organisations, branches and people. | E5: Tenant isolation enforced in the database; organisation hierarchy; Party model for people and companies | F5: Live | G5: All tenants | H5: platform/tenancy.ts, identity.ts | I5: S | K5: =INDEX('Pricing Rules'!$B$5:$B$8,MATCH(I5,'Pricing Rules'!$A$5:$A$8,0)) | L5: =INDEX('Pricing Rules'!$C$5:$C$8,MATCH(I5,'Pricing Rules'!$A$5:$A$8,0)) | M5: =IF(OR(F5="Live",F5="Live (client-built)"),"Yes",IF(F5="Partial","Yes, with limits","No")) | N5: Your data is walled off from every other client at database level, not just in the app. | O5: Tables: Tenant, Organization, Party. RLS via withTenant().
A6: M002 | B6: Platform Foundation | C6: Users, Roles & Permissions | D6: Define who can see and do what, down to individual fields. | E6: Roles and role composition; permission matrix; field-level permissions | F6: Live | G6: All tenants | H6: platform/authorization.ts | I6: S | J6: M001 | K6: =INDEX('Pricing Rules'!$B$5:$B$8,MATCH(I6,'Pricing Rules'!$A$5:$A$8,0)) | L6: =INDEX('Pricing Rules'!$C$5:$C$8,MATCH(I6,'Pricing Rules'!$A$5:$A$8,0)) | M6: =IF(OR(F6="Live",F6="Live (client-built)"),"Yes",IF(F6="Partial","Yes, with limits","No")) | N6: Warehouse sees stock, finance sees money, owner sees everything, set once. | O6: Tables: Role, RoleComposition, Permission, FieldPermission. UI: /roles, /people.
A7: M003 | B7: Platform Foundation | C7: SSO / OIDC Login | D7: Staff sign in with the company identity provider. | E7: OIDC browser flow; external auth adapter; password reset and verification | F7: Live | G7: OIDC lab identity | H7: platform/oidc.ts, external-auth.ts | I7: M | J7: M001 | K7: =INDEX('Pricing Rules'!$B$5:$B$8,MATCH(I7,'Pricing Rules'!$A$5:$A$8,0)) | L7: =INDEX('Pricing Rules'!$C$5:$C$8,MATCH(I7,'Pricing Rules'!$A$5:$A$8,0)) | M7: =IF(OR(F7="Live",F7="Live (client-built)"),"Yes",IF(F7="Partial","Yes, with limits","No")) | N7: Plug into the client's existing sign-in instead of another password. | O7: Tables: Credential, OidcLoginTransaction. Routes: /sign-in, /reset-password.
A8: M004 | B8: Platform Foundation | C8: Audit Trail & Activity History | D8: Who changed what and when, on every record, impossible to edit. | E8: Append-only audit events; per-record timeline; security audit events; audit viewer | F8: Live | G8: All tenants | H8: platform/audit.ts | I8: S | J8: M001 | K8: =INDEX('Pricing Rules'!$B$5:$B$8,MATCH(I8,'Pricing Rules'!$A$5:$A$8,0)) | L8: =INDEX('Pricing Rules'!$C$5:$C$8,MATCH(I8,'Pricing Rules'!$A$5:$A$8,0)) | M8: =IF(OR(F8="Live",F8="Live (client-built)"),"Yes",IF(F8="Partial","Yes, with limits","No")) | N8: Every change has a name and a timestamp. | O8: Tables: Activity, SecurityAuditEvent, DomainEvent. UI: /audit, /hq/audit.
A9: M005 | B9: Platform Foundation | C9: Workflow & State Engine | D9: Every record moves through defined states, and the rules are configurable. | E9: State definitions and transitions; workflow nodes, edges, runs; guarded transitions | F9: Live | G9: All tenants | H9: platform/workflow.ts, state.ts | I9: M | J9: M001 | K9: =INDEX('Pricing Rules'!$B$5:$B$8,MATCH(I9,'Pricing Rules'!$A$5:$A$8,0)) | L9: =INDEX('Pricing Rules'!$C$5:$C$8,MATCH(I9,'Pricing Rules'!$A$5:$A$8,0)) | M9: =IF(OR(F9="Live",F9="Live (client-built)"),"Yes",IF(F9="Partial","Yes, with limits","No")) | N9: Orders, invoices, leave and approvals all follow the same enforced path. | O9: Tables: StateDefinition, TransitionDefinition, WorkflowDefinition/Node/Edge/Run/StepRun.
A10: M006 | B10: Platform Foundation | C10: Approvals | D10: Multi-step approval chains by role, in sequence. | E10: Approval by role not person; ordered steps; rejection ends chain; comments; inbox | F10: Live | G10: Kent's, Shree Ganesh | H10: capabilities/approval | I10: S | J10: M005 | K10: =INDEX('Pricing Rules'!$B$5:$B$8,MATCH(I10,'Pricing Rules'!$A$5:$A$8,0)) | L10: =INDEX('Pricing Rules'!$C$5:$C$8,MATCH(I10,'Pricing Rules'!$A$5:$A$8,0)) | M10: =IF(OR(F10="Live",F10="Live (client-built)"),"Yes",IF(F10="Partial","Yes, with limits","No")) | N10: Spend above a limit goes to the right person automatically and survives staff changes. | O10: Commands: approval.request, approval.decide. UI: /approvals.
A11: M007 | B11: Platform Foundation | C11: Notifications | D11: In-app notifications driven by business events, with templates and preferences. | E11: Notification templates; preferences; written transactionally with the business change | F11: Partial | G11: All tenants | H11: platform/notification.ts | I11: M | J11: M005 | K11: =INDEX('Pricing Rules'!$B$5:$B$8,MATCH(I11,'Pricing Rules'!$A$5:$A$8,0)) | L11: =INDEX('Pricing Rules'!$C$5:$C$8,MATCH(I11,'Pricing Rules'!$A$5:$A$8,0)) | M11: =IF(OR(F11="Live",F11="Live (client-built)"),"Yes",IF(F11="Partial","Yes, with limits","No")) | N11: Overdue, approvals and low stock reach the person who owns them. | O11: In-app only. Email/WhatsApp/SMS delivery adapters not built (see M155).
A12: M008 | B12: Platform Foundation | C12: SLA Clocks & Business Calendar | D12: Deadlines that respect working hours and holidays. | E12: SLA policies and clocks; business calendars, hours, holidays | F12: Live | G12: Platform | H12: platform/sla.ts, temporal.ts | I12: M | J12: M001 | K12: =INDEX('Pricing Rules'!$B$5:$B$8,MATCH(I12,'Pricing Rules'!$A$5:$A$8,0)) | L12: =INDEX('Pricing Rules'!$C$5:$C$8,MATCH(I12,'Pricing Rules'!$A$5:$A$8,0)) | M12: =IF(OR(F12="Live",F12="Live (client-built)"),"Yes",IF(F12="Partial","Yes, with limits","No")) | N12: Response and delivery deadlines count working time only. | O12: Tables: SlaPolicy, SlaClock, BusinessCalendar, BusinessHours, BusinessHoliday.
A13: M009 | B13: Platform Foundation | C13: Custom Fields & Configuration | D13: Add fields and settings per client without code. | E13: Custom field schemas per entity; config parameters; settings pages | F13: Live | G13: All tenants | H13: platform/config.ts | I13: S | J13: M001 | K13: =INDEX('Pricing Rules'!$B$5:$B$8,MATCH(I13,'Pricing Rules'!$A$5:$A$8,0)) | L13: =INDEX('Pricing Rules'!$C$5:$C$8,MATCH(I13,'Pricing Rules'!$A$5:$A$8,0)) | M13: =IF(OR(F13="Live",F13="Live (client-built)"),"Yes",IF(F13="Partial","Yes, with limits","No")) | N13: Track the extra thing this business cares about without a developer. | O13: Tables: CustomFieldSchema, ConfigParameter. UI: /configuration, /settings.
A14: M010 | B14: Platform Foundation | C14: Industry Packs & Templates | D14: Install a pre-built industry setup in one step. | E14: Pack releases, instances, operations; template definitions and instances | F14: Live | G14: Plywood, Kent's | H14: platform/pack.ts, template.ts | I14: M | J14: M011 | K14: =INDEX('Pricing Rules'!$B$5:$B$8,MATCH(I14,'Pricing Rules'!$A$5:$A$8,0)) | L14: =INDEX('Pricing Rules'!$C$5:$C$8,MATCH(I14,'Pricing Rules'!$A$5:$A$8,0)) | M14: =IF(OR(F14="Live",F14="Live (client-built)"),"Yes",IF(F14="Partial","Yes, with limits","No")) | N14: Start from a proven setup for your industry, then tune it. | O14: Tables: PackRelease/Instance/Operation/Contribution/Event, TemplateDefinition/Instance.
A15: M011 | B15: Platform Foundation | C15: Capability Activation & Upgrades | D15: Switch modules on per client and upgrade safely. | E15: Per-tenant activation; dependency enforcement by DB trigger; upgrade operations | F15: Live | G15: All tenants | H15: platform/capability.ts, capability-upgrade.ts | I15: M | J15: M001 | K15: =INDEX('Pricing Rules'!$B$5:$B$8,MATCH(I15,'Pricing Rules'!$A$5:$A$8,0)) | L15: =INDEX('Pricing Rules'!$C$5:$C$8,MATCH(I15,'Pricing Rules'!$A$5:$A$8,0)) | M15: =IF(OR(F15="Live",F15="Live (client-built)"),"Yes",IF(F15="Partial","Yes, with limits","No")) | N15: Pay for and see only the modules you use; add more later with no migration. | O15: Tables: CapabilityDefinition, TenantActivation, CapabilityUpgradeOperation. UI: /capabilities.
A16: M012 | B16: Platform Foundation | C16: Files & Storage | D16: Documents and attachments stored per client with access control. | E16: Stored file records; pluggable storage backend; checksum-verified files | F16: Live | G16: Outreach research files | H16: platform/files.ts, storage | I16: S | J16: M001 | K16: =INDEX('Pricing Rules'!$B$5:$B$8,MATCH(I16,'Pricing Rules'!$A$5:$A$8,0)) | L16: =INDEX('Pricing Rules'!$C$5:$C$8,MATCH(I16,'Pricing Rules'!$A$5:$A$8,0)) | M16: =IF(OR(F16="Live",F16="Live (client-built)"),"Yes",IF(F16="Partial","Yes, with limits","No")) | N16: Attach the contract, photo or PDF to the record it belongs to. | O16: Table: StoredFile.
A17: M013 | B17: Platform Foundation | C17: Offline Sync Runtime | D17: Commands captured offline replay safely when back online. | E17: Idempotent inbox; ordered replay; optimistic concurrency; conflict surfacing | F17: Partial | G17: None live | H17: platform/sync.ts | I17: L | J17: M001 | K17: =INDEX('Pricing Rules'!$B$5:$B$8,MATCH(I17,'Pricing Rules'!$A$5:$A$8,0)) | L17: =INDEX('Pricing Rules'!$C$5:$C$8,MATCH(I17,'Pricing Rules'!$A$5:$A$8,0)) | M17: =IF(OR(F17="Live",F17="Live (client-built)"),"Yes",IF(F17="Partial","Yes, with limits","No")) | N17: Shop-floor and field work survives bad connectivity. | O17: Runtime only. No installable PWA shell or client queue UI. Tables: OfflineCommand, SyncException.
A18: M014 | B18: Platform Foundation | C18: API Keys & External Tool Invocation | D18: Let other systems call Verity commands securely. | E18: External API keys; idempotency keys; tool manifest; /api/tools/invoke; quotas | F18: Partial | G18: None live | H18: platform/external-tools.ts, tool-manifest.ts | I18: L | J18: M002 | K18: =INDEX('Pricing Rules'!$B$5:$B$8,MATCH(I18,'Pricing Rules'!$A$5:$A$8,0)) | L18: =INDEX('Pricing Rules'!$C$5:$C$8,MATCH(I18,'Pricing Rules'!$A$5:$A$8,0)) | M18: =IF(OR(F18="Live",F18="Live (client-built)"),"Yes",IF(F18="Partial","Yes, with limits","No")) | N18: Connect an outside system without opening the database. | O18: Tables: ExternalApiKey, ExternalIdempotency, RequestQuota. Relay integration is ADR-029 proposed (Task 120). No public API docs.
A19: M015 | B19: Platform Foundation | C19: Security Hardening | D19: Rate limits, strict CSP, redaction and telemetry scrubbing. | E19: Shared rate limiting; CSP; log redaction; request size limits | F19: Live | G19: Platform | H19: platform/rate-limit.ts, csp.ts, redaction.ts | I19: S | K19: =INDEX('Pricing Rules'!$B$5:$B$8,MATCH(I19,'Pricing Rules'!$A$5:$A$8,0)) | L19: =INDEX('Pricing Rules'!$C$5:$C$8,MATCH(I19,'Pricing Rules'!$A$5:$A$8,0)) | M19: =IF(OR(F19="Live",F19="Live (client-built)"),"Yes",IF(F19="Partial","Yes, with limits","No")) | N19: Built-in protection against abuse and accidental data leaks. | O19: Enterprise-hardening claims need the evidence programme (Task 123) finished.
A20: M016 | B20: Platform Foundation | C20: HQ Operator Console | D20: PlotArmour's own console to run every client workspace. | E20: Client list; per-client modules, packs, people, roles, organisations, operations, settings | F20: Live | G20: PlotArmour internal | H20: src/app/(hq) | I20: M | J20: M011 | K20: =INDEX('Pricing Rules'!$B$5:$B$8,MATCH(I20,'Pricing Rules'!$A$5:$A$8,0)) | L20: =INDEX('Pricing Rules'!$C$5:$C$8,MATCH(I20,'Pricing Rules'!$A$5:$A$8,0)) | M20: =IF(OR(F20="Live",F20="Live (client-built)"),"Yes",IF(F20="Partial","Yes, with limits","No")) | N20: One place to onboard, configure and support every client. | O20: Routes: /hq, /hq/clients/[tenantId]/*. Internal, not sold.
A21: M017 | B21: Platform Foundation | C21: Data Import & Migration | D21: Bring items, customers and suppliers across from Excel or an old system. | E21: Import wizard; duplicate handling; item, customer, supplier scope | F21: Partial | G21: Shree Ganesh | H21: server/actions/import.ts | I21: M | J21: M001 | K21: =INDEX('Pricing Rules'!$B$5:$B$8,MATCH(I21,'Pricing Rules'!$A$5:$A$8,0)) | L21: =INDEX('Pricing Rules'!$C$5:$C$8,MATCH(I21,'Pricing Rules'!$A$5:$A$8,0)) | M21: =IF(OR(F21="Live",F21="Live (client-built)"),"Yes",IF(F21="Partial","Yes, with limits","No")) | N21: Day-one data without retyping. | O21: Only item, customer and supplier import. Orders, balances, ledgers not importable. UI: /import.
A22: M018 | B22: Platform Foundation | C22: Dashboards & Workspaces | D22: Role-based home screens with live KPIs and sparklines. | E22: Overview dashboard; workspace home; metric snapshots with history | F22: Live | G22: All tenants | H22: platform/dashboard.ts | I22: S | J22: M001 | K22: =INDEX('Pricing Rules'!$B$5:$B$8,MATCH(I22,'Pricing Rules'!$A$5:$A$8,0)) | L22: =INDEX('Pricing Rules'!$C$5:$C$8,MATCH(I22,'Pricing Rules'!$A$5:$A$8,0)) | M22: =IF(OR(F22="Live",F22="Live (client-built)"),"Yes",IF(F22="Partial","Yes, with limits","No")) | N22: Open Verity and see today's business, not last month's report. | O22: UI: /overview, /workspace. Table: TradingMetricSnapshot.
A23: M019 | B23: Platform Foundation | C23: Verity AI Assistant | D23: Ask questions in plain language, answered from the client's own records. | E23: Permission-aware agent chat; grounded answers; tool manifest; bulk ops with partial failure | F23: Live | G23: All tenants | H23: platform/agent-chat.ts, grounding.ts | I23: L | J23: M002 | K23: =INDEX('Pricing Rules'!$B$5:$B$8,MATCH(I23,'Pricing Rules'!$A$5:$A$8,0)) | L23: =INDEX('Pricing Rules'!$C$5:$C$8,MATCH(I23,'Pricing Rules'!$A$5:$A$8,0)) | M23: =IF(OR(F23="Live",F23="Live (client-built)"),"Yes",IF(F23="Partial","Yes, with limits","No")) | N23: Ask which customers owe more than 30 days and get the answer with the records behind it. | O23: Model/API usage not metered or priced; set allowance in Pricing Rules.
A24: M020 | B24: Platform Foundation | C24: Jev Decision Node (AI advisory in workflows) | D24: An AI advice step inside a workflow under seven safety constraints. | E24: Workflow node verity.decision.ask; needs egress capability and API key | F24: Built, not live-verified | G24: None | H24: platform/decision.ts | I24: L | J24: M005, M019 | K24: =INDEX('Pricing Rules'!$B$5:$B$8,MATCH(I24,'Pricing Rules'!$A$5:$A$8,0)) | L24: =INDEX('Pricing Rules'!$C$5:$C$8,MATCH(I24,'Pricing Rules'!$A$5:$A$8,0)) | M24: =IF(OR(F24="Live",F24="Live (client-built)"),"Yes",IF(F24="Partial","Yes, with limits","No")) | N24: AI recommends, a human decides, everything is logged. | O24: Unit-proven only. Needs migration, key, one real call (Task 119). Do not sell yet.
A25: M021 | B25: Platform Foundation | C25: Reports & MIS | D25: Standard sales, purchase, inventory and finance reports. | E25: Report hub; sales, purchases, inventory, finance reports; date-range filters | F25: Live | G25: Shree Ganesh, Kent's | H25: src/app/(shell)/reports | I25: M | K25: =INDEX('Pricing Rules'!$B$5:$B$8,MATCH(I25,'Pricing Rules'!$A$5:$A$8,0)) | L25: =INDEX('Pricing Rules'!$C$5:$C$8,MATCH(I25,'Pricing Rules'!$A$5:$A$8,0)) | M25: =IF(OR(F25="Live",F25="Live (client-built)"),"Yes",IF(F25="Partial","Yes, with limits","No")) | N25: The reports owners ask for every Monday, already built. | O25: UI: /reports/*. No custom report builder (see M160).
A26: M030 | B26: Locations & Field | C26: Locations, Places & Geofences | D26: Sites, outlets and godowns with addresses and map boundaries. | E26: Location records with custom fields; place and address; geofences; user assignment | F26: Live | G26: Kent's, Shree Ganesh | H26: capabilities/location | I26: S | J26: M001 | K26: =INDEX('Pricing Rules'!$B$5:$B$8,MATCH(I26,'Pricing Rules'!$A$5:$A$8,0)) | L26: =INDEX('Pricing Rules'!$C$5:$C$8,MATCH(I26,'Pricing Rules'!$A$5:$A$8,0)) | M26: =IF(OR(F26="Live",F26="Live (client-built)"),"Yes",IF(F26="Partial","Yes, with limits","No")) | N26: Multi-site from day one: outlets, godowns, offices. | O26: 7 commands. UI: /locations, /godowns.
A27: M031 | B27: Locations & Field | C27: Assets & Equipment Register | D27: Track machines, vehicles and equipment with state and location. | E27: Asset register; state changes; relocation; no industry-specific columns | F27: Live | G27: Platform | H27: capabilities/asset | I27: S | J27: M030 | K27: =INDEX('Pricing Rules'!$B$5:$B$8,MATCH(I27,'Pricing Rules'!$A$5:$A$8,0)) | L27: =INDEX('Pricing Rules'!$C$5:$C$8,MATCH(I27,'Pricing Rules'!$A$5:$A$8,0)) | M27: =IF(OR(F27="Live",F27="Live (client-built)"),"Yes",IF(F27="Partial","Yes, with limits","No")) | N27: Know where every asset is and what condition it is in. | O27: UI: /assets.
A28: M032 | B28: Locations & Field | C28: Evidence Capture | D28: Photos, GPS and signatures that cannot be altered afterwards. | E28: Append-only evidence records; geofence-checked capture | F28: Live | G28: Platform | H28: capabilities/evidence | I28: M | J28: M030, M012 | K28: =INDEX('Pricing Rules'!$B$5:$B$8,MATCH(I28,'Pricing Rules'!$A$5:$A$8,0)) | L28: =INDEX('Pricing Rules'!$C$5:$C$8,MATCH(I28,'Pricing Rules'!$A$5:$A$8,0)) | M28: =IF(OR(F28="Live",F28="Live (client-built)"),"Yes",IF(F28="Partial","Yes, with limits","No")) | N28: Proof of delivery or inspection that stands up in a dispute. | O28: UI: /evidence.
A29: M033 | B29: Locations & Field | C29: Scheduling & Resource Booking | D29: Book people, rooms and equipment without double-booking. | E29: Resources backed by a person or asset; resource groups; availability; bookings | F29: Live | G29: Platform | H29: capabilities/scheduling | I29: M | J29: M031 | K29: =INDEX('Pricing Rules'!$B$5:$B$8,MATCH(I29,'Pricing Rules'!$A$5:$A$8,0)) | L29: =INDEX('Pricing Rules'!$C$5:$C$8,MATCH(I29,'Pricing Rules'!$A$5:$A$8,0)) | M29: =IF(OR(F29="Live",F29="Live (client-built)"),"Yes",IF(F29="Partial","Yes, with limits","No")) | N29: Crews, rooms and machines scheduled against real availability. | O29: UI: /scheduling.
A30: M040 | B30: Sales & Trading | C30: Customers & Credit | D30: Customer master with credit limits and customer-specific pricing. | E30: Customer records; credit limit and approval; customer price lists; supplier linking | F30: Live | G30: Shree Ganesh | H30: capabilities/trading | I30: S | J30: M001 | K30: =INDEX('Pricing Rules'!$B$5:$B$8,MATCH(I30,'Pricing Rules'!$A$5:$A$8,0)) | L30: =INDEX('Pricing Rules'!$C$5:$C$8,MATCH(I30,'Pricing Rules'!$A$5:$A$8,0)) | M30: =IF(OR(F30="Live",F30="Live (client-built)"),"Yes",IF(F30="Partial","Yes, with limits","No")) | N30: Know who owes you and stop shipping to those over limit. | O30: Commands: create/edit/remove_customer, set_credit_limit, approve_credit, set_customer_price. UI: /customers.
A31: M041 | B31: Sales & Trading | C31: Suppliers & Supplier Prices | D31: Supplier master with price history per item. | E31: Supplier records; supplier price sets; supplier-customer linking | F31: Live | G31: Shree Ganesh | H31: capabilities/trading | I31: S | J31: M001 | K31: =INDEX('Pricing Rules'!$B$5:$B$8,MATCH(I31,'Pricing Rules'!$A$5:$A$8,0)) | L31: =INDEX('Pricing Rules'!$C$5:$C$8,MATCH(I31,'Pricing Rules'!$A$5:$A$8,0)) | M31: =IF(OR(F31="Live",F31="Live (client-built)"),"Yes",IF(F31="Partial","Yes, with limits","No")) | N31: Compare what each supplier charged last time before you order. | O31: UI: /suppliers.
A32: M042 | B32: Sales & Trading | C32: Product Catalogue | D32: Products with brand, HSN code and tax details. | E32: Brands; products; active flags; catalogue admin | F32: Live | G32: Shree Ganesh | H32: capabilities/trading | I32: S | K32: =INDEX('Pricing Rules'!$B$5:$B$8,MATCH(I32,'Pricing Rules'!$A$5:$A$8,0)) | L32: =INDEX('Pricing Rules'!$C$5:$C$8,MATCH(I32,'Pricing Rules'!$A$5:$A$8,0)) | M32: =IF(OR(F32="Live",F32="Live (client-built)"),"Yes",IF(F32="Partial","Yes, with limits","No")) | N32: One clean catalogue behind sales, purchase and stock. | O32: UI: /catalogue. Pack-specific attributes live in packs such as plywood.
A33: M043 | B33: Sales & Trading | C33: Sales Orders | D33: Create, edit, reserve stock for and fulfil customer orders. | E33: Order lines; stock reservation; fulfilment; cancel; order timeline | F33: Live | G33: Shree Ganesh | H33: capabilities/trading | I33: M | J33: M040, M042 | K33: =INDEX('Pricing Rules'!$B$5:$B$8,MATCH(I33,'Pricing Rules'!$A$5:$A$8,0)) | L33: =INDEX('Pricing Rules'!$C$5:$C$8,MATCH(I33,'Pricing Rules'!$A$5:$A$8,0)) | M33: =IF(OR(F33="Live",F33="Live (client-built)"),"Yes",IF(F33="Partial","Yes, with limits","No")) | N33: From order to dispatch on one record. | O33: UI: /sales, /sales/[orderId]. No quotation step (see M152).
A34: M044 | B34: Sales & Trading | C34: Sales Invoicing & Notes | D34: GST invoices with series, credit notes and debit notes. | E34: Invoice series; sales invoices; invoice notes | F34: Live | G34: Shree Ganesh | H34: capabilities/trading | I34: M | J34: M043 | K34: =INDEX('Pricing Rules'!$B$5:$B$8,MATCH(I34,'Pricing Rules'!$A$5:$A$8,0)) | L34: =INDEX('Pricing Rules'!$C$5:$C$8,MATCH(I34,'Pricing Rules'!$A$5:$A$8,0)) | M34: =IF(OR(F34="Live",F34="Live (client-built)"),"Yes",IF(F34="Partial","Yes, with limits","No")) | N34: Invoices numbered and taxed correctly the first time. | O34: UI: /finance, /finance/[invoiceId].
A35: M045 | B35: Sales & Trading | C35: Payments & Receivables | D35: Record payments and allocate them against invoices. | E35: Payments; allocations; party payments; outstanding view; ledgers | F35: Live | G35: Shree Ganesh | H35: capabilities/trading | I35: M | J35: M044 | K35: =INDEX('Pricing Rules'!$B$5:$B$8,MATCH(I35,'Pricing Rules'!$A$5:$A$8,0)) | L35: =INDEX('Pricing Rules'!$C$5:$C$8,MATCH(I35,'Pricing Rules'!$A$5:$A$8,0)) | M35: =IF(OR(F35="Live",F35="Live (client-built)"),"Yes",IF(F35="Partial","Yes, with limits","No")) | N35: See at a glance who has paid and who has not. | O35: UI: /transactions, /ledgers. No online gateway (see M076).
A36: M046 | B36: Sales & Trading | C36: Purchase Orders & Goods Receipt | D36: Raise purchase orders and receive goods against them. | E36: PO create, edit, submit, cancel; goods receipt; partial receipts | F36: Live | G36: Shree Ganesh | H36: capabilities/trading | I36: M | J36: M041 | K36: =INDEX('Pricing Rules'!$B$5:$B$8,MATCH(I36,'Pricing Rules'!$A$5:$A$8,0)) | L36: =INDEX('Pricing Rules'!$C$5:$C$8,MATCH(I36,'Pricing Rules'!$A$5:$A$8,0)) | M36: =IF(OR(F36="Live",F36="Live (client-built)"),"Yes",IF(F36="Partial","Yes, with limits","No")) | N36: Know what is on order, what arrived and what is short. | O36: UI: /purchases.
A37: M047 | B37: Sales & Trading | C37: Purchase Bills & Review Queue | D37: Turn supplier bills into confirmed purchase entries. | E37: Purchase invoice; bill from order; confirmation queue | F37: Live | G37: Shree Ganesh | H37: capabilities/trading | I37: M | J37: M046 | K37: =INDEX('Pricing Rules'!$B$5:$B$8,MATCH(I37,'Pricing Rules'!$A$5:$A$8,0)) | L37: =INDEX('Pricing Rules'!$C$5:$C$8,MATCH(I37,'Pricing Rules'!$A$5:$A$8,0)) | M37: =IF(OR(F37="Live",F37="Live (client-built)"),"Yes",IF(F37="Partial","Yes, with limits","No")) | N37: Supplier bills checked against what was actually received. | O37: Commands: raise_purchase_invoice, raise_purchase_bill_from_order, confirm_purchase_bill.
A38: M048 | B38: Sales & Trading | C38: Stock Ledger & Godowns | D38: Every stock movement recorded, by godown and rack. | E38: Receive, issue, transfer, adjust, damage, return; racks; balances; reservations | F38: Live | G38: Shree Ganesh | H38: capabilities/trading | I38: L | J38: M042, M030 | K38: =INDEX('Pricing Rules'!$B$5:$B$8,MATCH(I38,'Pricing Rules'!$A$5:$A$8,0)) | L38: =INDEX('Pricing Rules'!$C$5:$C$8,MATCH(I38,'Pricing Rules'!$A$5:$A$8,0)) | M38: =IF(OR(F38="Live",F38="Live (client-built)"),"Yes",IF(F38="Partial","Yes, with limits","No")) | N38: Stock you can trust because every unit has a history. | O38: UI: /stock, /godowns. Append-only ledger.
A39: M049 | B39: Sales & Trading | C39: Price Sheets & Customer Pricing | D39: Different prices for different customers and periods. | E39: Price sheets; customer overrides; supplier price sets | F39: Live | G39: Shree Ganesh | H39: capabilities/trading | I39: S | J39: M040 | K39: =INDEX('Pricing Rules'!$B$5:$B$8,MATCH(I39,'Pricing Rules'!$A$5:$A$8,0)) | L39: =INDEX('Pricing Rules'!$C$5:$C$8,MATCH(I39,'Pricing Rules'!$A$5:$A$8,0)) | M39: =IF(OR(F39="Live",F39="Live (client-built)"),"Yes",IF(F39="Partial","Yes, with limits","No")) | N39: Quote consistently, protect margin. | O39: UI: /prices.
A40: M050 | B40: Sales & Trading | C40: GST Compliance Workspace | D40: Prepare GSTR-1 and GSTR-3B, track input tax credit, reconcile with the portal. | E40: Tax rule sets; GSTR-1, GSTR-3B; ITC; portal record import; exceptions; period close | F40: Live | G40: Shree Ganesh | H40: capabilities/trading (tax, itc, period) | I40: L | J40: M044, M047 | K40: =INDEX('Pricing Rules'!$B$5:$B$8,MATCH(I40,'Pricing Rules'!$A$5:$A$8,0)) | L40: =INDEX('Pricing Rules'!$C$5:$C$8,MATCH(I40,'Pricing Rules'!$A$5:$A$8,0)) | M40: =IF(OR(F40="Live",F40="Live (client-built)"),"Yes",IF(F40="Partial","Yes, with limits","No")) | N40: Return preparation without exporting to Excel. Preparation only, Verity does not file. | O40: UI: /tax/*. Website copy rule forbids the phrase GST filing.
A41: M051 | B41: Sales & Trading | C41: Accounting Periods & Ledgers | D41: Close months, lock them, reopen with a record. | E41: Accounting periods; ledger entries; party ledgers | F41: Live | G41: Shree Ganesh | H41: capabilities/trading | I41: M | J41: M045 | K41: =INDEX('Pricing Rules'!$B$5:$B$8,MATCH(I41,'Pricing Rules'!$A$5:$A$8,0)) | L41: =INDEX('Pricing Rules'!$C$5:$C$8,MATCH(I41,'Pricing Rules'!$A$5:$A$8,0)) | M41: =IF(OR(F41="Live",F41="Live (client-built)"),"Yes",IF(F41="Partial","Yes, with limits","No")) | N41: Closed months stay closed. | O41: Commands: close_period, reopen_period.
...

Sheet Pricing Rules
A1: Pricing Rules & Commercial Policy
A2: Blue cells are inputs. Every price formula in Modules, Packages and Quick Quote reads from here. All figures are proposed 2026 list rates, ex-GST.
A4: Complexity | B4: Add-on setup fee | C4: Add-on monthly fee | D4: Meaning
A5: S | B5: 10000 | C5: 500 | D5: Configuration only: switch on, set roles, load masters
A6: M | B6: 25000 | C6: 1000 | D6: Configuration plus workflow mapping and a short training
A7: L | B7: 40000 | C7: 2000 | D7: Multiple workflows, integrations between modules, data mapping
A8: XL | B8: 60000 | C8: 3500 | D8: Large module or pack: significant mapping and acceptance testing
A10: Assumptions
A11: GST rate | B11: 0.18 | C11: Assumed 18% on services. Confirm with finance. Tax is extra to every price shown.
A12: Annual prepay discount | B12: 0.125 | C12: Midpoint of the 10 to 15 percent policy range from the previous workbook.
A13: Extra location setup fee | B13: 10000 | C13: Per location beyond the first. PROPOSED, not in the old workbook.
A14: Extra location monthly fee | B14: 1000 | C14: Per location beyond the first. PROPOSED, not in the old workbook.
A15: Recommended minimum implementation | B15: 125000 | C15: From old policy. Conflicts with package floors, see Pricing Review item 1.
A16: Recommended minimum monthly platform fee | B16: 12000 | C16: From old policy. Conflicts with package floors, see Pricing Review item 2.
A18: Commercial policy (carried over from the previous workbook, wording unchanged)
A19: Commercial item | B19: Recommended policy
A20: Implementation fee | B20: One-time fee covering configuration, setup, workflow mapping, base customization, testing and deployment.
A21: Subscription | B21: Monthly platform/support fee. Final amount depends on modules, users, environment, integrations and SLA.
A22: User licensing | B22: Recommended to avoid aggressive per-seat pricing for MSMEs; use business/package tiers, with user caps only where necessary.
A23: Custom development | B23: Quoted separately using the Verity Customization rate card or a fixed project quote.
A24: Integrations | B24: Third-party API, WhatsApp/SMS, accounting, payment gateway and external platform charges are billed separately where applicable.
A25: AI usage | B25: Model/API usage costs should be passed through or included with a clearly defined monthly allowance.
A26: Hosting | B26: Can be bundled into subscription or quoted separately for dedicated environments.
A27: Data migration | B27: Always scope separately based on source system, volume, cleanup and mapping complexity.
A28: Onboarding | B28: Standard onboarding included in implementation. Complex process consulting/training can be charged separately.
A29: Support | B29: Standard support included in subscription; priority SLA/dedicated support is an add-on.
A30: Annual billing | B30: Offer 10–15% effective discount for annual prepayment where commercially appropriate.
... A34: Pricing status | B34: These are proposed Verity 2026 commercial rates, not historical prices unless separately verified from a quotation/invoice.

Sheet Customization Rates
A1: Customization Rate Card
A2: Per-item rates for work beyond the package. Numbers are from the previous workbook. Open-ended means the Advanced figure is a floor.
A4: Customization | B4: Billing basis | C4: Basic | D4: Standard | E4: Advanced | F4: Charge type | G4: Open-ended? | H4: Build status note
A5: Custom field / field group | B5: Per field/group | C5: 1000 | D5: 2500 | E5: 5000 | F5: One-time | G5: Yes
A6: Custom status / workflow stage | B6: Per workflow | C6: 2500 | D6: 5000 | E6: 10000 | F6: One-time | G6: Yes
A7: Approval workflow | B7: Per workflow | C7: 5000 | D7: 10000 | E7: 25000 | F7: One-time | G7: Yes
A8: Custom form / data-entry screen | B8: Per screen | C8: 5000 | D8: 10000 | E8: 25000 | F8: One-time | G8: Yes
A9: Custom report | B9: Per report | C9: 3000 | D9: 7500 | E9: 20000 | F9: One-time | G9: Yes | H9: Standard reports exist (M021).
A10: Custom dashboard | B10: Per dashboard | C10: 7500 | D10: 15000 | E10: 35000 | F10: One-time | G10: Yes
A11: Custom PDF / document template | B11: Per template | C11: 3000 | D11: 7500 | E11: 15000 | F11: One-time | G11: Yes
A12: Third-party API integration | B12: Per integration | C12: 10000 | D12: 25000 | E12: 50000 | F12: One-time | G12: Yes
A13: Accounting / ERP integration | B13: Per integration | C13: 20000 | D13: 50000 | E13: 100000 | F13: One-time | G13: Yes | H13: No connector exists (M075). Quote as a build.
A14: WhatsApp / SMS integration | B14: Per integration | C14: 10000 | D14: 25000 | E14: 50000 | F14: One-time | G14: Yes | H14: Channel not built (M155). Quote only as a build.
A15: Custom PWA/offline workflow | B15: Per workflow | C15: 15000 | D15: 35000 | E15: 75000 | F15: One-time | G15: Yes | H15: Offline runtime exists, no PWA shell (M013).
A16: AI feature / assistant | B16: Per feature | C16: 20000 | D16: 50000 | E16: 100000 | F16: One-time | G16: Yes | H16: AI assistant is live (M019). Usage cost is separate.
A17: Data migration | B17: Per migration project | C17: 10000 | D17: 25000 | E17: 75000 | F17: One-time | G17: Yes | H17: Import covers items, customers, suppliers only (M017).
A18: Custom module | B18: Per module | C18: 30000 | D18: 75000 | E18: 200000 | F18: One-time | G18: Yes | H18: Platform supports registering capabilities (M011).
A19: Client portal | B19: Per portal | C19: 25000 | D19: 60000 | E19: 150000 | F19: One-time | G19: Yes | H19: Not built (M154). Quote as a build.
A20: Mobile-specific workflow | B20: Per workflow | C20: 15000 | D20: 35000 | E20: 75000 | F20: One-time | G20: Yes | H20: Web app is responsive; native not built.
A21: Custom analytics / BI | B21: Per implementation | C21: 20000 | D21: 50000 | E21: 150000 | F21: One-time | G21: Yes | H21: No report builder (M160). Quote as a build.
A22: Priority SLA / dedicated support | B22: Monthly add-on | C22: 10000 | D22: 20000 | E22: 50000 | F22: Monthly | G22: Yes

Sheet Pricing Review
A1: Pricing Review: open issues in the commercial model
A2: Found while reconciling the previous workbook with the codebase. Nothing here was silently changed. Resolve, then update Pricing Rules / Packages.
A4: # | B4: Area | C4: Issue | D4: Evidence | E4: Impact | F4: Recommendation | G4: Severity | H4: Status | I4: Owner / decision
A5: 1 | B5: Policy | C5: Recommended minimum implementation (Rs 1.25 lakh) is higher than every package setup floor except Manufacturing Plus, Enterprise and Dedicated. | D5: Core 40,000; Trade 50,000; Services 75,000; Production 90,000 against a 1,25,000 minimum. | E5: Packages Core to Production can never be sold at their listed floor if the minimum is enforced. | F5: Decide: drop the minimum, raise the floors, or call it a minimum for custom scope only. | G5: High | H5: Open
A6: 2 | B6: Policy | C6: Recommended minimum recurring fee (Rs 12,000/mo) is higher than every package monthly fee below Enterprise. | D6: Core 2,000; Trade 3,000; Services 5,000; Production 8,000; Mfg Plus 10,000. | E6: Same conflict as item 1 for recurring revenue. | F6: Pick one rule and state it on Packages. | G6: High | H6: Open
A7: 3 | B7: Scope | C7: Verity Core promises quotations. Quotations are not built. | D7: No quotation entity in code. Only purchase orders exist (M152 Planned). | E7: Sales would be selling a module that does not exist. | F7: Build M152, or remove quotations from Core scope until it ships. | G7: High | H7: Open
